<?xml version="1.0" ?>

<robot xmlns:xacro="http://ros.org/wiki/xacro" >

  <xacro:macro name="camera_effector" >

    <!-- Links -->
    <link name="camera_effector_pan_link" >
      <!-- FIXME -->
      <xacro:solid_cuboid_inertial mass="0.057" x="0.041" y="0.050" z="0.035" >
        <origin xyz="0.00234 0.01566 -0.0002" />
      </xacro:solid_cuboid_inertial>
      <visual>
        <geometry>
          <mesh filename="package://pandora_robots_description/gio/meshes/camera_effector_pan_servo_link.dae" />
        </geometry>
      </visual>
      <collision>
        <origin xyz="0.0 -0.00585 0.01588" />
        <geometry>
          <box size="0.012 0.032 0.029" />
        </geometry>
      </collision>
    </link>

    <link name="camera_effector_base_link" >
      <xacro:solid_cuboid_inertial mass="0.010" x="0.051" y="0.053" z="0.005" >
        <origin xyz="-0.0045 -0.00011 0.00069" />
      </xacro:solid_cuboid_inertial>
      <visual>
        <geometry>
          <mesh filename="package://pandora_robots_description/gio/meshes/camera_effector_pan_base_link.dae" />
        </geometry>
      </visual>
      <collision>picam/meshes/raspberry_pi_camera
        <origin xyz="0.00027 -0.00042 0.00104" />
        <geometry>
          <box size="0.051 0.053 0.005" />
        </geometry>
      </collision>
    </link>

    <link name="camera_effector_tilt_link" >
      <xacro:solid_cuboid_inertial mass="0.020" x="0.012" y="0.029" z="0.032" >
        <origin xyz="0.0 -0.01887 -0.00518" />
      </xacro:solid_cuboid_inertial>
      <visual>
        <geometry>
          <mesh filename="package://pandora_robots_description/gio/meshes/camera_effector_tilt_servo_link.dae" />
        </geometry>
      </visual>
      <collision>
        <origin xyz="0.0 -0.01588 -0.00585" />
        <geometry>
          <box size="0.012 0.029 0.032" />
        </geometry>
      </collision>
    </link>

    <link name="camera_effector_platform_link" >
      <!-- FIXME -->
      <inertial>
        <origin xyz="-0.00329 -0.02726 0.05623" />
        <mass value="0.16491" />
        <inertia ixx="0.00030418"
                 ixy="-1.3735E-05"
                 ixz="-2.3947E-05"
                 iyy="0.00015881"
                 iyz="-7.9817E-06"
                 izz="0.00024855" />
      </inertial>
      <visual>
        <geometry>
          <mesh filename="package://pandora_robots_description/gio/meshes/camera_effector_platform.dae" />
        </geometry>
      </visual>
      <collision>
        <origin xyz="0.0 -0.01925 0.00324" />
        <geometry>
          <box size="0.011 0.050 0.030" />
        </geometry>
      </collision>
    </link>

    <!-- Joints -->
    <joint name="camera_effector_pan_joint"
           type="revolute" >
      <parent link="linear_actuator_link" />
      <child link="camera_effector_pan_link" />
      <origin xyz="0.0 0.0 0.15614" />
      <axis xyz="0 0 1" />
      <dynamics damping="0.0" />
      <limit lower="${camera_effector_pan_joint_min_limit}"
             upper="${camera_effector_pan_joint_max_limit}"
             effort="50.0"
             velocity="50.0" />
    </joint>

    <joint name="camera_effector_pan_base_joint"
           type="fixed" >
      <parent link="camera_effector_pan_link" />
      <child link="camera_effector_base_link" />
      <origin xyz="0.00355 0.0 0.01003" />
    </joint>

    <joint name="camera_effector_tilt_base_joint"
           type="fixed" >
      <parent link="camera_effector_base_link" />
      <child link="camera_effector_tilt_link" />
      <origin xyz="0.01036 0.02302 0.01931" />
    </joint>

    <joint name="camera_effector_tilt_joint"
           type="revolute" >
      <parent link="camera_effector_tilt_link" />
      <child link="camera_effector_platform_link" />
      <origin xyz="0.0 0.0 0.0"
              rpy="0.0 0.3490658504 0.0" />
      <axis xyz="0 1 0" />
      <dynamics damping="0.0" />
      <limit lower="${camera_effector_tilt_joint_min_limit}"
             upper="${camera_effector_tilt_joint_max_limit}"
             effort="50.0"
             velocity="50.0" />
    </joint>

  </xacro:macro>

</robot>
