<?xml version="1.0" ?>

<robot xmlns:xacro="http://ros.org/wiki/xacro" >

  <xacro:property name="wheelbase" value="0.32" />
  <xacro:property name="track" value="0.26" />

  <xacro:property name="steer_link_offset" value="0.115" />
  <xacro:property name="steer_link_radius" value="0.008" />
  <xacro:property name="steer_link_mass" value="0.001" />

  <xacro:property name="drive_link_length" value="0.03" />
  <xacro:property name="drive_link_radius" value="0.0025" />
  <xacro:property name="drive_link_mass" value="0.001" />

  <xacro:property name="wheel_link_radius" value="0.075" />
  <xacro:property name="wheel_link_width" value="0.081" />
  <xacro:property name="wheel_link_offset" value="-0.004" />
  <xacro:property name="wheel_link_mass" value="0.281" />

  <xacro:macro name="offroad_wheel"
    params="prefix_y prefix_x reflect_y reflect_x" >

    <joint name="${prefix_y}_${prefix_x}_wheel_steer_joint" type="revolute" >
      <parent link="${prefix_x}_axle_link" />
      <child link="${prefix_y}_${prefix_x}_wheel_steer_link" />
      <origin xyz="0.0 ${reflect_y*steer_link_offset} 0.0" />
      <axis xyz="0 0 1" />
      <dynamics damping="0.0" />
      <limit
        lower="${steer_joint_min_limit}"
        upper="${steer_joint_max_limit}"
        effort="${steer_joint_effort_limit}"
        velocity="${steer_joint_velocity_limit}"/>
    </joint>

    <!-- wheel steer link -->
    <link name="${prefix_y}_${prefix_x}_wheel_steer_link" >
      <xacro:solid_sphere_inertial
        mass="${steer_link_mass}"
        radius="${steer_link_radius}" >
        <origin xyz="0.0 0.0 0.0" />
      </xacro:solid_sphere_inertial>
      <visual>
        <origin xyz="0.0 0.0 0.0" rpy="0.0 0.0 0.0" />
        <geometry>
          <sphere radius="${steer_link_radius}" />
        </geometry>
        <material name="dark_grey" />
      </visual>
      <collision>
        <origin xyz="0.0 0.0 0.0" rpy="0.0 0.0 0.0" />
        <geometry>
          <sphere radius="${steer_link_radius}" />
        </geometry>
      </collision>
    </link>

    <!-- wheel steer link to drive link joint -->
    <joint name="${prefix_y}_${prefix_x}_wheel_steer_link_to_drive_link_joint" type="fixed" >
      <parent link="${prefix_y}_${prefix_x}_wheel_steer_link" />
      <child link="${prefix_y}_${prefix_x}_wheel_drive_link" />
      <origin xyz="0.0 ${reflect_y*(steer_link_radius/2+drive_link_length/2)} 0.0" />
    </joint>

    <!-- wheel drive link -->
    <link name="${prefix_y}_${prefix_x}_wheel_drive_link" >
      <!-- Using real inertia causes unexpected bahaviour -->
      <!-- Works fine, only with null inertial -->
      <xacro:null_inertial />
      <!-- <xacro:solid_cylinder_inertial mass="0.01" radius="0.0025" y="0.03" > -->
        <!-- <origin xyz="0.0 0.0 0.0" /> -->
      <!-- </xacro:solid_cylinder_inertial> -->
      <visual>
        <origin xyz="0.0 0.0 0.0" rpy="${PI/2} 0.0 0.0" />
        <geometry>
          <cylinder radius="${drive_link_radius}" length="${drive_link_length}" />
        </geometry>
        <material name="dark_grey" />
      </visual>
      <collision>
        <origin xyz="0.0 0.0 0.0" rpy="${PI/2} 0.0 0.0" />
        <geometry>
          <cylinder radius="${drive_link_radius}" length="${drive_link_length}" />
        </geometry>
      </collision>
    </link>

    <!-- drive link to wheel joint -->
    <joint name="${prefix_y}_${prefix_x}_wheel_drive_joint" type="continuous" >
      <parent link="${prefix_y}_${prefix_x}_wheel_drive_link" />
      <child link="${prefix_y}_${prefix_x}_wheel_link" />
      <origin xyz="0.0 ${reflect_y*wheel_link_offset} 0.0" />
      <axis xyz="0 1 0" />
      <dynamics damping="0.0" />
      <limit
        effort="${drive_joint_effort_limit}"
        velocity="${drive_joint_velocity_limit}" />
    </joint>

    <!-- wheel_link -->
    <link name="${prefix_y}_${prefix_x}_wheel_link" >
      <xacro:solid_cylinder_inertial
        mass="${wheel_link_mass}"
        radius="${wheel_link_radius}"
        y="${wheel_link_width}" >
        <origin xyz="0.0 0.0 0.0" />
      </xacro:solid_cylinder_inertial>
      <visual>
        <origin xyz="0.0 0.0 0.0" rpy="0.0 0.0 0.0" />
        <geometry>
          <mesh filename="package://pandora_robots_description/monstertruck/meshes/${prefix_y}_offroad_wheel.dae" />
        </geometry>
      </visual>
      <collision>
        <origin xyz="0.0 0.0 0.0" rpy="${PI/2} 0.0 0.0" />
        <geometry>
          <!-- <mesh filename="package://pandora_robots_description/monstertruck/meshes/${prefix_y}_offroad_wheel.stl" /> -->
          <cylinder radius="${wheel_link_radius}" length="${wheel_link_width}" />
        </geometry>
      </collision>
    </link>

  </xacro:macro>

</robot>
