<?xml version="1.0" ?>

<robot xmlns:xacro="http://ros.org/wiki/xacro" >

  <xacro:property name="wheelbase" value="0.32" />
  <xacro:property name="track" value="0.26" />

  <xacro:property name="steer_link_x_offset" value="0.028" />
  <xacro:property name="steer_link_y_offset" value="0.0525" />
  <xacro:property name="steer_link_z_offset" value="-0.051" />
  <xacro:property name="steer_link_radius" value="0.008" />
  <xacro:property name="steer_link_mass" value="0.001" />

  <xacro:property name="drive_link_length" value="0.03" />
  <xacro:property name="drive_link_radius" value="0.0025" />
  <xacro:property name="drive_link_mass" value="0.005" />

  <xacro:property name="wheel_link_radius" value="0.075" />
  <xacro:property name="wheel_link_width" value="0.081" />
  <xacro:property name="wheel_link_offset" value="-0.004" />
  <xacro:property name="wheel_link_mass" value="0.281" />

  <xacro:macro name="offroad_wheel"
    params="prefix_y prefix_x reflect_y reflect_x" >

    <joint name="${prefix_y}_${prefix_x}_wheel_suspension_joint" type="prismatic" >
      <parent link="base_link" />
      <child link="${prefix_y}_${prefix_x}_wheel_suspension_link" />
      <limit
        effort="${wheel_suspension_joint_effort_limit}"
        velocity="${wheel_suspension_joint_velocity_limit}"
        lower="${wheel_suspension_joint_lower_limit}"
        upper="${wheel_suspension_joint_upper_limit}" />
      <dynamics damping="20.0" />
      <origin xyz="${reflect_x*0.158+0.031} ${reflect_y*0.115} -0.077"  rpy="0.0 0.0 0.0" />
      <axis xyz="0 0 1" />
    </joint>

    <link name="${prefix_y}_${prefix_x}_wheel_suspension_link">
      <xacro:null_inertial />
    </link>

    <joint name="${prefix_y}_${prefix_x}_wheel_steer_joint" type="revolute" >
      <parent link="${prefix_y}_${prefix_x}_wheel_suspension_link" />
      <child link="${prefix_y}_${prefix_x}_wheel_steer_link" />
      <origin xyz="0.0 0.0 0.0" />
      <axis xyz="0 0 1" />
      <dynamics damping="0.0" />
      <limit
        lower="${steer_joint_lower_limit}"
        upper="${steer_joint_upper_limit}"
        effort="${steer_joint_effort_limit}"
        velocity="${steer_joint_velocity_limit}"/>
    </joint>

    <!-- wheel steer link -->
    <link name="${prefix_y}_${prefix_x}_wheel_steer_link" >
      <!-- Using real inertia causes unstable bahaviour -->
      <!-- Works fine, only with null inertial -->
      <!-- <xacro:solid_sphere_inertial -->
        <!-- mass="${steer_link_mass}" -->
        <!-- radius="${steer_link_radius}" > -->
        <!-- <origin xyz="0.0 0.0 0.0" /> -->
      <!-- </xacro:solid_sphere_inertial> -->
      <xacro:null_inertial />
      <visual>
        <origin xyz="0.0 0.0 0.0" rpy="0.0 0.0 0.0" />
        <geometry>
          <sphere radius="${steer_link_radius}" />
        </geometry>
        <material name="dark_grey" />
      </visual>
      <collision>
        <origin xyz="0.0 0.0 0.0" rpy="0.0 0.0 0.0" />
        <geometry>
          <sphere radius="${steer_link_radius}" />
        </geometry>
      </collision>
    </link>

    <!-- wheel steer link to drive link joint -->
    <joint name="${prefix_y}_${prefix_x}_wheel_drive_joint" type="continuous" >
      <parent link="${prefix_y}_${prefix_x}_wheel_steer_link" />
      <child link="${prefix_y}_${prefix_x}_wheel_drive_link" />
      <origin xyz="0.0 ${reflect_y*(steer_link_radius/2+drive_link_length/2)} 0.0" />
      <axis xyz="0 1 0" />
      <dynamics damping="0.0" />
      <limit
        effort="${drive_joint_effort_limit}"
        velocity="${drive_joint_velocity_limit}" />
    </joint>

    <!-- wheel drive link -->
    <link name="${prefix_y}_${prefix_x}_wheel_drive_link" >
      <xacro:solid_cylinder_inertial
        mass="${drive_link_mass}"
        radius="${drive_link_radius}"
        y="${drive_link_length}" >
        <origin xyz="0.0 0.0 0.0" />
      </xacro:solid_cylinder_inertial>
      <visual>
        <origin xyz="0.0 0.0 0.0" rpy="${PI/2} 0.0 0.0" />
        <geometry>
          <cylinder radius="${drive_link_radius}" length="${drive_link_length}" />
        </geometry>
        <material name="dark_grey" />
      </visual>
      <collision>
        <origin xyz="0.0 0.0 0.0" rpy="${PI/2} 0.0 0.0" />
        <geometry>
          <cylinder radius="${drive_link_radius}" length="${drive_link_length}" />
        </geometry>
      </collision>
    </link>

    <!-- drive link to wheel joint -->
    <joint name="${prefix_y}_${prefix_x}_wheel_joint" type="fixed" >
      <parent link="${prefix_y}_${prefix_x}_wheel_drive_link" />
      <child link="${prefix_y}_${prefix_x}_wheel_link" />
      <origin xyz="0.0 ${reflect_y*wheel_link_offset} 0.0" />
    </joint>

    <!-- wheel_link -->
    <link name="${prefix_y}_${prefix_x}_wheel_link" >
      <xacro:solid_cylinder_inertial
        mass="${wheel_link_mass}"
        radius="${wheel_link_radius}"
        y="${wheel_link_width}" >
        <origin xyz="0.0 0.0 0.0" />
      </xacro:solid_cylinder_inertial>
      <visual>
        <origin xyz="0.0 0.0 0.0" rpy="${PI/2*0} 0.0 0.0" />
        <geometry>
          <mesh filename="package://pandora_robots_description/monstertruck/meshes/${prefix_y}_offroad_wheel.dae" />
          <!-- <cylinder radius="${wheel_link_radius}" length="${wheel_link_width}" /> -->
        </geometry>
      </visual>
      <collision>
        <origin xyz="0.0 0.0 0.0" rpy="${PI/2} 0.0 0.0" />
        <geometry>
          <!-- <mesh filename="package://pandora_robots_description/monstertruck/meshes/${prefix_y}_offroad_wheel.stl" /> -->
          <cylinder radius="${wheel_link_radius}" length="${wheel_link_width}" />
        </geometry>
      </collision>
    </link>

  </xacro:macro>

</robot>
